Workbook

Sheet 汇总
B1: isaacsim | C1: poli | D1: vsi | E1: imageNet1K
A2: A4 | B2: =MATCH(A2,isaacsim!$A$2:$A$154,0) -> 1 | C2: =MATCH(A2,poli!$A$2:$A$154,0) -> #N/A | D2: =MATCH(A2,vsi!$A$2:$A$154,0) -> #N/A | E2: =MATCH(A2,imageNet1K!$A$2:$E$1001,0) -> #N/A | F2: =IFERROR(OR(B2,C2,D2),0) -> 0
A3: AdvertisingBannerQAParking | B3: =MATCH(A3,isaacsim!$A$2:$A$154,0) -> 2 | C3: =MATCH(A3,poli!$A$2:$A$154,0) -> #N/A | D3: =MATCH(A3,vsi!$A$2:$A$154,0) -> #N/A | E3: =MATCH(A3,imageNet1K!$A$2:$E$1001,0) -> #N/A | F3: =IFERROR(OR(B3,C3,D3),0) -> 0
A4: AirShaft | B4: =MATCH(A4,isaacsim!$A$2:$A$154,0) -> 3 | C4: =MATCH(A4,poli!$A$2:$A$154,0) -> #N/A | D4: =MATCH(A4,vsi!$A$2:$A$154,0) -> #N/A | E4: =MATCH(A4,imageNet1K!$A$2:$E$1001,0) -> #N/A | F4: =IFERROR(OR(B4,C4,D4),0) -> 0
A5: AlarmClock | B5: =MATCH(A5,isaacsim!$A$2:$A$154,0) -> #N/A | C5: =MATCH(A5,poli!$A$2:$A$154,0) -> 2 | D5: =MATCH(A5,vsi!$A$2:$A$154,0) -> #N/A | E5: =MATCH(A5,imageNet1K!$A$2:$E$1001,0) -> #N/A | F5: =IFERROR(OR(B5,C5,D5),0) -> 0
A6: Apple | B6: =MATCH(A6,isaacsim!$A$2:$A$154,0) -> #N/A | C6: =MATCH(A6,poli!$A$2:$A$154,0) -> 3 | D6: =MATCH(A6,vsi!$A$2:$A$154,0) -> #N/A | E6: =MATCH(A6,imageNet1K!$A$2:$E$1001,0) -> #N/A | F6: =IFERROR(OR(B6,C6,D6),0) -> 0
A7: Armchair | B7: =MATCH(A7,isaacsim!$A$2:$A$154,0) -> 4 | C7: =MATCH(A7,poli!$A$2:$A$154,0) -> #N/A | D7: =MATCH(A7,vsi!$A$2:$A$154,0) -> #N/A | E7: =MATCH(A7,imageNet1K!$A$2:$E$1001,0) -> #N/A | F7: =IFERROR(OR(B7,C7,D7),0) -> 0
A8: Backpack | B8: =MATCH(A8,isaacsim!$A$2:$A$154,0) -> #N/A | C8: =MATCH(A8,poli!$A$2:$A$154,0) -> #N/A | D8: =MATCH(A8,vsi!$A$2:$A$154,0) -> 47 | E8: =MATCH(A8,imageNet1K!$A$2:$E$1001,0) -> #N/A | F8: =IFERROR(OR(B8,C8,D8),0) -> 0
A9: BaseballBat | B9: =MATCH(A9,isaacsim!$A$2:$A$154,0) -> #N/A | C9: =MATCH(A9,poli!$A$2:$A$154,0) -> 4 | D9: =MATCH(A9,vsi!$A$2:$A$154,0) -> #N/A | E9: =MATCH(A9,imageNet1K!$A$2:$E$1001,0) -> #N/A | F9: =IFERROR(OR(B9,C9,D9),0) -> 0
A10: BaseballGlove | B10: =MATCH(A10,isaacsim!$A$2:$A$154,0) -> #N/A | C10: =MATCH(A10,poli!$A$2:$A$154,0) -> 5 | D10: =MATCH(A10,vsi!$A$2:$A$154,0) -> #N/A | E10: =MATCH(A10,imageNet1K!$A$2:$E$1001,0) -> #N/A | F10: =IFERROR(OR(B10,C10,D10),0) -> 0
A11: Basket | B11: =MATCH(A11,isaacsim!$A$2:$A$154,0) -> #N/A | C11: =MATCH(A11,poli!$A$2:$A$154,0) -> #N/A | D11: =MATCH(A11,vsi!$A$2:$A$154,0) -> 48 | E11: =MATCH(A11,imageNet1K!$A$2:$E$1001,0) -> #N/A | F11: =IFERROR(OR(B11,C11,D11),0) -> 0
A12: BasketBall | B12: =MATCH(A12,isaacsim!$A$2:$A$154,0) -> #N/A | C12: =MATCH(A12,poli!$A$2:$A$154,0) -> 6 | D12: =MATCH(A12,vsi!$A$2:$A$154,0) -> #N/A | E12: =MATCH(A12,imageNet1K!$A$2:$A$1001,0) -> 76 | F12: =IFERROR(OR(B12,C12,D12),0) -> 0
A13: Bathtub | B13: =MATCH(A13,isaacsim!$A$2:$A$154,0) -> #N/A | C13: =MATCH(A13,poli!$A$2:$A$154,0) -> #N/A | D13: =MATCH(A13,vsi!$A$2:$A$154,0) -> 40 | E13: =MATCH(A13,imageNet1K!$A$2:$E$1001,0) -> #N/A | F13: =IFERROR(OR(B13,C13,D13),0) -> 0
A14: Bed | B14: =MATCH(A14,isaacsim!$A$2:$A$154,0) -> #N/A | C14: =MATCH(A14,poli!$A$2:$A$154,0) -> 7 | D14: =MATCH(A14,vsi!$A$2:$A$154,0) -> 2 | E14: =MATCH(A14,imageNet1K!$A$2:$E$1001,0) -> #N/A | F14: =IFERROR(OR(B14,C14,D14),0) -> 0
A15: Billboard | B15: =MATCH(A15,isaacsim!$A$2:$A$154,0) -> 5 | C15: =MATCH(A15,poli!$A$2:$A$154,0) -> #N/A | D15: =MATCH(A15,vsi!$A$2:$A$154,0) -> #N/A | E15: =MATCH(A15,imageNet1K!$A$2:$E$1001,0) -> #N/A | F15: =IFERROR(OR(B15,C15,D15),0) -> 0
A16: Blanket | B16: =MATCH(A16,isaacsim!$A$2:$A$154,0) -> #N/A | C16: =MATCH(A16,poli!$A$2:$A$154,0) -> #N/A | D16: =MATCH(A16,vsi!$A$2:$A$154,0) -> 49 | E16: =MATCH(A16,imageNet1K!$A$2:$E$1001,0) -> #N/A | F16: =IFERROR(OR(B16,C16,D16),0) -> 0
A17: Blinds | B17: =MATCH(A17,isaacsim!$A$2:$A$154,0) -> 6 | C17: =MATCH(A17,poli!$A$2:$A$154,0) -> #N/A | D17: =MATCH(A17,vsi!$A$2:$A$154,0) -> #N/A | E17: =MATCH(A17,imageNet1K!$A$2:$E$1001,0) -> #N/A | F17: =IFERROR(OR(B17,C17,D17),0) -> 0
A18: Board | B18: =MATCH(A18,isaacsim!$A$2:$A$154,0) -> 7 | C18: =MATCH(A18,poli!$A$2:$A$154,0) -> #N/A | D18: =MATCH(A18,vsi!$A$2:$A$154,0) -> #N/A | E18: =MATCH(A18,imageNet1K!$A$2:$E$1001,0) -> #N/A | F18: =IFERROR(OR(B18,C18,D18),0) -> 0
A19: Book | B19: =MATCH(A19,isaacsim!$A$2:$A$154,0) -> 8 | C19: =MATCH(A19,poli!$A$2:$A$154,0) -> #N/A | D19: =MATCH(A19,vsi!$A$2:$A$154,0) -> #N/A | E19: =MATCH(A19,imageNet1K!$A$2:$E$1001,0) -> #N/A | F19: =IFERROR(OR(B19,C19,D19),0) -> 0
A20: BookOpen | B20: =MATCH(A20,isaacsim!$A$2:$A$154,0) -> 10 | C20: =MATCH(A20,poli!$A$2:$A$154,0) -> #N/A | D20: =MATCH(A20,vsi!$A$2:$A$154,0) -> #N/A | E20: =MATCH(A20,imageNet1K!$A$2:$E$1001,0) -> #N/A | F20: =IFERROR(OR(B20,C20,D20),0) -> 0
A21: Bookcase | B21: =MATCH(A21,isaacsim!$A$2:$A$154,0) -> 9 | C21: =MATCH(A21,poli!$A$2:$A$154,0) -> #N/A | D21: =MATCH(A21,vsi!$A$2:$A$154,0) -> #N/A | E21: =MATCH(A21,imageNet1K!$A$2:$E$1001,0) -> #N/A | F21: =IFERROR(OR(B21,C21,D21),0) -> 0
A22: BooksSet | B22: =MATCH(A22,isaacsim!$A$2:$A$154,0) -> 11 | C22: =MATCH(A22,poli!$A$2:$A$154,0) -> #N/A | D22: =MATCH(A22,vsi!$A$2:$A$154,0) -> #N/A | E22: =MATCH(A22,imageNet1K!$A$2:$E$1001,0) -> #N/A | F22: =IFERROR(OR(B22,C22,D22),0) -> 0
A23: Bottle | B23: =MATCH(A23,isaacsim!$A$2:$A$154,0) -> 12 | C23: =MATCH(A23,poli!$A$2:$A$154,0) -> #N/A | D23: =MATCH(A23,vsi!$A$2:$A$154,0) -> #N/A | E23: =MATCH(A23,imageNet1K!$A$2:$E$1001,0) -> #N/A | F23: =IFERROR(OR(B23,C23,D23),0) -> 0
A24: Bowl | B24: =MATCH(A24,isaacsim!$A$2:$A$154,0) -> #N/A | C24: =MATCH(A24,poli!$A$2:$A$154,0) -> 8 | D24: =MATCH(A24,vsi!$A$2:$A$154,0) -> 50 | E24: =MATCH(A24,imageNet1K!$A$2:$E$1001,0) -> #N/A | F24: =IFERROR(OR(B24,C24,D24),0) -> 0
... A38: CeilingLight | B38: =MATCH(A38,isaacsim!$A$2:$A$154,0) -> 23 | C38: =MATCH(A38,poli!$A$2:$A$154,0) -> #N/A | D38: =MATCH(A38,vsi!$A$2:$A$154,0) -> #N/A | E38: =MATCH(A38,imageNet1K!$A$2:$E$1001,0) -> #N/A | F38: =IFERROR(OR(B38,C38,D38),0) -> 0
A39: Chair | B39: =MATCH(A39,isaacsim!$A$2:$A$154,0) -> 24 | C39: =MATCH(A39,poli!$A$2:$A$154,0) -> 9 | D39: =IFERROR(MATCH(A39,vsi!$A$2:$A$154,0),0) -> 4 | E39: =MATCH(A39,imageNet1K!$A$2:$E$1001,0) -> #N/A | F39: =IFERROR(OR(B39,C39,D39),0) -> TRUE
A40: ChairOffice | B40: =MATCH(A40,isaacsim!$A$2:$A$154,0) -> 25 | C40: =MATCH(A40,poli!$A$2:$A$154,0) -> #N/A | D40: =MATCH(A40,vsi!$A$2:$A$154,0) -> #N/A | E40: =MATCH(A40,imageNet1K!$A$2:$E$1001,0) -> #N/A | F40: =IFERROR(OR(B40,C40,D40),0) -> 0
A41: Clock | B41: =MATCH(A41,isaacsim!$A$2:$A$154,0) -> 26 | C41: =MATCH(A41,poli!$A$2:$A$154,0) -> #N/A | D41: =MATCH(A41,vsi!$A$2:$A$154,0) -> 18 | E41: =MATCH(A41,imageNet1K!$A$2:$E$1001,0) -> #N/A | F41: =IFERROR(OR(B41,C41,D41),0) -> 0
A42: CoffeeToGo | B42: =MATCH(A42,isaacsim!$A$2:$A$154,0) -> 27 | C42: =MATCH(A42,poli!$A$2:$A$154,0) -> #N/A | D42: =MATCH(A42,vsi!$A$2:$A$154,0) -> #N/A | E42: =MATCH(A42,imageNet1K!$A$2:$E$1001,0) -> #N/A | F42: =IFERROR(OR(B42,C42,D42),0) -> 0
A43: Computer_Mouse | B43: =MATCH(A43,isaacsim!$A$2:$A$154,0) -> #N/A | C43: =MATCH(A43,poli!$A$2:$A$154,0) -> #N/A | D43: =MATCH(A43,vsi!$A$2:$A$154,0) -> #N/A | E43: =MATCH(A43,imageNet1K!$A$2:$E$1001,0) -> #N/A | F43: =IFERROR(OR(B43,C43,D43),0) -> 0
A44: Computer_Tower | B44: =MATCH(A44,isaacsim!$A$2:$A$154,0) -> #N/A | C44: =MATCH(A44,poli!$A$2:$A$154,0) -> #N/A | D44: =MATCH(A44,vsi!$A$2:$A$154,0) -> #N/A | E44: =MATCH(A44,imageNet1K!$A$2:$E$1001,0) -> #N/A | F44: =IFERROR(OR(B44,C44,D44),0) -> 0
A45: Counter | B45: =MATCH(A45,isaacsim!$A$2:$A$154,0) -> #N/A | C45: =MATCH(A45,poli!$A$2:$A$154,0) -> #N/A | D45: =MATCH(A45,vsi!$A$2:$A$154,0) -> 7 | E45: =MATCH(A45,imageNet1K!$A$2:$E$1001,0) -> #N/A | F45: =IFERROR(OR(B45,C45,D45),0) -> 0
A46: Crate | B46: =MATCH(A46,isaacsim!$A$2:$A$154,0) -> #N/A | C46: =MATCH(A46,poli!$A$2:$A$154,0) -> #N/A | D46: =MATCH(A46,vsi!$A$2:$A$154,0) -> 52 | E46: =MATCH(A46,imageNet1K!$A$2:$E$1001,0) -> #N/A | F46: =IFERROR(OR(B46,C46,D46),0) -> 0
A47: CreditCard | B47: =MATCH(A47,isaacsim!$A$2:$A$154,0) -> #N/A | C47: =MATCH(A47,poli!$A$2:$A$154,0) -> 10 | D47: =MATCH(A47,vsi!$A$2:$A$154,0) -> #N/A | E47: =MATCH(A47,imageNet1K!$A$2:$E$1001,0) -> #N/A | F47: =IFERROR(OR(B47,C47,D47),0) -> 0
A48: Cube | B48: =MATCH(A48,isaacsim!$A$2:$A$154,0) -> 31 | C48: =MATCH(A48,poli!$A$2:$A$154,0) -> #N/A | D48: =MATCH(A48,vsi!$A$2:$A$154,0) -> #N/A | E48: =MATCH(A48,imageNet1K!$A$2:$E$1001,0) -> #N/A | F48: =IFERROR(OR(B48,C48,D48),0) -> 0
A49: Cushion | B49: =MATCH(A49,isaacsim!$A$2:$A$154,0) -> #N/A | C49: =MATCH(A49,poli!$A$2:$A$154,0) -> #N/A | D49: =MATCH(A49,vsi!$A$2:$A$154,0) -> 8 | E49: =MATCH(A49,imageNet1K!$A$2:$E$1001,0) -> #N/A | F49: =IFERROR(OR(B49,C49,D49),0) -> 0
A50: Cup | B50: =MATCH(A50,isaacsim!$A$2:$A$154,0) -> 32 | C50: =MATCH(A50,poli!$A$2:$A$154,0) -> 11 | D50: =MATCH(A50,vsi!$A$2:$A$154,0) -> 53 | E50: =MATCH(A50,imageNet1K!$A$2:$E$1001,0) -> #N/A | F50: =IFERROR(OR(B50,C50,D50),0) -> TRUE
A51: Cupboard | B51: =MATCH(A51,isaacsim!$A$2:$A$154,0) -> 33 | C51: =MATCH(A51,poli!$A$2:$A$154,0) -> #N/A | D51: =MATCH(A51,vsi!$A$2:$A$154,0) -> #N/A | E51: =MATCH(A51,imageNet1K!$A$2:$E$1001,0) -> #N/A | F51: =IFERROR(OR(B51,C51,D51),0) -> 0
... A205: Window | B205: =MATCH(A205,isaacsim!$A$2:$A$154,0) -> 153 | C205: =MATCH(A205,poli!$A$2:$A$154,0) -> #N/A | D205: =MATCH(A205,vsi!$A$2:$A$154,0) -> 46 | E205: =MATCH(A205,imageNet1K!$A$2:$E$1001,0) -> #N/A | F205: =IFERROR(OR(B205,C205,D205),0) -> 0

Sheet isaacsim
A2: A4
A3: AdvertisingBannerQAParking
A4: AirShaft
A5: Armchair
A6: Billboard
A7: Blinds
A8: Board
A9: Book
A10: Bookcase
A11: BookOpen
A12: BooksSet
A13: Bottle
... A154: Window

Sheet poli
A2: 英文名称 | B2: 中文名称
A3: AlarmClock | B3: 闹钟 | C3: =MATCH(A3,isaacsim!$A$2:$A$154,0) -> #N/A
A4: Apple | B4: 苹果 | C4: =MATCH(A4,isaacsim!$A$2:$A$154,0) -> #N/A
A5: BaseballBat | B5: 棒球棒 | C5: =MATCH(A5,isaacsim!$A$2:$A$154,0) -> #N/A
A6: BaseballGlove | B6: 棒球手套 | C6: =MATCH(A6,isaacsim!$A$2:$A$154,0) -> #N/A
A7: BasketBall | B7: 篮球 | C7: =MATCH(A7,isaacsim!$A$2:$A$154,0) -> #N/A
A8: Bed | B8: 床 | C8: =MATCH(A8,isaacsim!$A$2:$A$154,0) -> #N/A
A9: Bowl | B9: 碗 | C9: =MATCH(A9,isaacsim!$A$2:$A$154,0) -> #N/A
A10: Chair | B10: 椅子 | C10: =MATCH(A10,isaacsim!$A$2:$A$154,0) -> 24
A11: CreditCard | B11: 信用卡 | C11: =MATCH(A11,isaacsim!$A$2:$A$154,0) -> #N/A
A12: Cup | B12: 杯子 | C12: =MATCH(A12,isaacsim!$A$2:$A$154,0) -> 32
A13: Laptop | B13: 笔记本电脑 | C13: =MATCH(A13,isaacsim!$A$2:$A$154,0) -> 70
A14: Mug | B14: 马克杯 | C14: =MATCH(A14,isaacsim!$A$2:$A$154,0) -> #N/A
... A23: Vase | B23: 花瓶 | C23: =MATCH(A23,isaacsim!$A$2:$A$154,0) -> 147

Sheet vsi
A2: 英文名称 | B2: 中文名称
A3: bed | B3: 床 | C3: =MATCH(A3,isaacsim!$A$2:$A$154,0) -> #N/A
A4: bookshelf | B4: 书架 | C4: =MATCH(A4,isaacsim!$A$2:$A$154,0) -> #N/A
A5: chair | B5: 椅子 | C5: =MATCH(A5,isaacsim!$A$2:$A$154,0) -> 24
A6: closet | B6: 衣柜 | C6: =MATCH(A6,isaacsim!$A$2:$A$154,0) -> #N/A
A7: coat rack | B7: 衣帽架 | C7: =MATCH(A7,isaacsim!$A$2:$A$154,0) -> #N/A
A8: counter | B8: 柜台/台面 | C8: =MATCH(A8,isaacsim!$A$2:$A$154,0) -> #N/A
A9: cushion | B9: 坐垫 | C9: =MATCH(A9,isaacsim!$A$2:$A$154,0) -> #N/A
A10: mattress | B10: 床垫 | C10: =MATCH(A10,isaacsim!$A$2:$A$154,0) -> #N/A
A11: nightstand | B11: 床头柜 | C11: =MATCH(A11,isaacsim!$A$2:$A$154,0) -> #N/A
A12: piano | B12: 钢琴 | C12: =MATCH(A12,isaacsim!$A$2:$A$154,0) -> #N/A
A13: shoe rack | B13: 鞋架 | C13: =MATCH(A13,isaacsim!$A$2:$A$154,0) -> #N/A
A14: sofa | B14: 沙发 | C14: =MATCH(A14,isaacsim!$A$2:$A$154,0) -> 129
... A64: trash can | B64: 垃圾桶 | C64: =MATCH(A64,isaacsim!$A$2:$A$154,0) -> #N/A

Sheet imageNet1K
A1: A | B1: B | C1: C | D1: D
A2: abacus
A3: abaya
A4: academic gown | B4: academic robe | C4: judge's robe
A5: accordion | B5: piano accordion | C5: squeeze box
A6: acorn
A7: acorn squash
A8: acoustic guitar
A9: admiral
A10: affenpinscher | B10: monkey pinscher | C10: monkey dog
A11: Afghan hound | B11: Afghan
A12: African chameleon | B12: Chamaeleo chamaeleon
A13: African crocodile | B13: Nile crocodile | C13: Crocodylus niloticus
A14: African elephant | B14: Loxodonta africana
A15: African grey | B15: African gray | C15: Psittacus erithacus
A16: African hunting dog | B16: hyena dog | C16: Cape hunting dog | D16: Lycaon pictus
A17: agama
A18: agaric
A19: aircraft carrier | B19: carrier | C19: flattop | D19: attack aircraft carrier
A20: Airedale | B20: Airedale terrier
A21: airliner
A22: airship | B22: dirigible
A23: albatross | B23: mollymawk
A24: alligator lizard
A25: alp
A26: altar
A27: ambulance
A28: American alligator | B28: Alligator mississipiensis
A29: American black bear | B29: black bear | C29: Ursus americanus | D29: Euarctos americanus
A30: American chameleon | B30: anole | C30: Anolis carolinensis
A31: American coot | B31: marsh hen | C31: mud hen | D31: water hen | E31: Fulica americana
A32: American egret | B32: great white heron | C32: Egretta albus
A33: American lobster | B33: Northern lobster | C33: Maine lobster | D33: Homarus americanus
A34: American Staffordshire terrier | B34: Staffordshire terrier | C34: American pit bull terrier | D34: pit bull terrier
A35: amphibian | B35: amphibious vehicle
A36: analog clock
A37: anemone fish
A38: Angora | B38: Angora rabbit
A39: ant | B39: emmet | C39: pismire
A40: apiary | B40: bee house
...
